<robot xmlns:xacro="http://wiki.ros.org/xacro" name="abitobot">
    <xacro:macro name="robot_wheel" params="prefix y">
        <link name="wheel_${prefix}_link">
            <collision name="wheel_${prefix}_collision">
                <origin rpy="-0.00000 0.00000 0.00000" xyz="0.00000 -0.00000 -0.00000"/>
                <geometry>
                    <mesh filename="file://$(find abitobot)/meshes/dae/wheel_${prefix}.dae" scale="0.28000 0.28000 0.60000"/>
                </geometry>
                <surface>
                  <friction>
                    <ode>
                      <mu>1.000000</mu>
                      <mu2>1.000000</mu2>
                      <fdir1>0.000000 0.000000 1.000000</fdir1>
                      <slip1>0.500000</slip1>
                      <slip2>0.500000</slip2>
                    </ode>
                  </friction>
                </surface>
            </collision>
            <inertial>
                <inertia ixx="0.16584" ixy="0.00000" ixz="0.00000" iyy="0.28737" iyz="0.00000" izz="0.16584"/>
                <origin rpy="0.00000 0.00000 0.00000" xyz="-0.00000 -0.00000 -0.00000"/>
                <mass value="5.00000"/>
            </inertial>
            <visual name="wheel_${prefix}">
                <origin rpy="-0.00000 0.00000 0.00000" xyz="0.00000 -0.00000 -0.00000"/>
                <material name="black"/>
                <geometry>
                    <mesh filename="file://$(find abitobot)/meshes/dae/wheel_${prefix}.dae" scale="0.28000 0.28000 0.60000"/>
                </geometry>
            </visual>
        </link>

        <joint name="wheel_${prefix}_joint" type="continuous">
            <limit effort="5000" velocity="100"/>
            <dynamics damping="0.05" friction="0.1"/>
            <origin rpy="1.57080 0.00000 ${y}" xyz="-0.00000 0.18824 -0.04412"/>
            <parent link="leg_${prefix}_link"/>
            <child link="wheel_${prefix}_link"/>
            <axis xyz="0.00000 0.00000 1.00000"/>
        </joint>

        <transmission name="wheel_${prefix}_joint_trans">
          <type>transmission_interface/SimpleTransmission</type>
          <joint name="wheel_${prefix}_joint">
            <hardwareInterface>hardware_interface/VelocityJointInterface</hardwareInterface>
          </joint>
          <actuator name="wheel_${prefix}_joint_motor">
            <mechanicalReduction>1</mechanicalReduction>
          </actuator>
        </transmission>
    
        <gazebo reference="wheel_${prefix}_link">
          <mu1>5</mu1>
          <mu2>5</mu2>
          <!-- <kp>2.75e6</kp>
          <kd>8.25e1</kd>
          <fdir1>0 0 0</fdir1>
          <maxContacts>4</maxContacts> -->
        </gazebo>
        
    </xacro:macro>
</robot>